Workbook

Sheet dashboard
A1: 💄 SOCIOLLA FRAGRANCE MARKET
A5: Product, brand & customer review overview
A7: OVERVIEW
B9: =COUNTA(products!A:A) -> 475 | F9: =COUNTA(brands!A:A) -> 55 | J9: =COUNTA(reviews!A:A) -> 30491 | N9: =MEDIAN(productmetrics!D:D) -> 229000 | R9: =COUNTIF(productmetrics!E2:E1000,">=4,5")/COUNT(productmetrics!A2:A1000) -> 0.65611814
B13: PRODUCTS | F13: BRANDS | J13: REVIEWS | N13: MEDIAN PRICE | R13: ≥4.5 RATING
B17: TOP 10 BRANDS | I17: RATING DISTRIBUTION | P17: PRODUCT PERFORMANCE
E38: TOP 10 PRODUCTS | L38: BRAND PERFORMANCE

Sheet metrics
A1: overview | C1: total brands | D1: =COUNTA(brands!A:A) -> 55
C2: total products | D2: =COUNTA(products!A:A) -> 475
C3: total reviews | D3: =COUNTA(reviews!A:A) -> 30491
C4: % products with reviews | D4: =IFERROR(__xludf.DUMMYFUNCTION("COUNTUNIQUE(FILTER(reviews!B2:B997,reviews!B2:B997<>""""))/COUNTUNIQUE(FILTER(products!A2:A997,products!A2:A997<>""""))"),0.7848101265822784) -> 0.78481013

Sheet productmetrics
A1: product_id | B1: product_name | C1: brand_id | D1: price | E1: avg_rating | F1: description | G1: review_count | H1: brand_name
A2: 110247 | B2: HMNS x Tsana Fragrance Mist - Elea | C2: 62c7f51270c7e2af7c6ad720 | D2: 185000 | E2: 4.743803 | F2: <p>Pertama kali kamu bertemu Elea nanti, tutup mata kamu. Kamu akan dengan mudah mengenalinya dari rambut panjangnya, dan wangi bunga magnolianya. Yang cantik &amp; terasa hijau seperti magnolia yang baru saja dipetik.<br>Sebentar setelah kamu di dekatnya, kamu sadar kalau Elea lebih kompleks dari setangkai bunga magnolia. Elea seperti puluhan kombinasi bunga putih yang terikat dengan madu dan minyak biji ambrette. Dia terasa dekat, terasa hangat.<br>Dan untuk sesaat dalam waktu yang panjang, kamu sadar kalau akhirnya..<br>Kamu gak sendirian.<br>[Product Detail]<br>Type: Eau de Toilette<br>Group: White Floral<br>Size: 250 ml<br>Longevity: 2 - 3 hours<br>Sillage: Medium<br>Projection: 1 - 2.5 meters</p> | G2: 939 | H2: HMNS
A3: 117020 | B3: IRAI LEIMA - Extrait de Parfum | C3: 60d4e2c6443396b9504d4beb | D3: 349000 | E3: 4.8344444 | F3: <p>Parfum aquatic yang membawa sensasi udara laut segar, air yang tenang, dan drydown hangat yang terasa lembut di kulit.</p><br /><p>NOTES<br>TOP: Cassis Buds, Dalanghita, Pink Pepper<br>MID: Duchesse de Nemours, Water Iris, Raat ki Rani<br>BASE: Warm Musky Notes</p><br /><p>Cocok buat kamu yang suka parfum aquatic floral yang fresh dan soft!</p><br /><p>- Long-Lasting Scent, tahan lama untuk menemani aktivitasmu<br>- Perfect for Daily Wear, wangi yang pas dan nyaman untuk aktivitas sehari-hari</p><br /><p>Cara Pakai<br>- Semprot pada titik nadi dengan jarak 15-20 cm<br>- Tunggu hingga kering</p> | G3: 541 | H3: SAFF & Co
A4: 98385 | B4: S.O.T.B - Extrait de Parfum | C4: 60d4e2c6443396b9504d4beb | D4: 349000 | E4: 4.857915 | F4: <p>Parfum yang menangkap summer dream: kulit yang sun-kissed, beach breeze, dan suasana tropical yang fun sepanjang hari.</p><br /><p>NOTES<br>TOP: Mandarin<br>MID: Sweet Floral Notes<br>BASE: Vanilla Musk</p><br /><p>Cocok buat kamu yang suka parfum tropical floral yang fresh dan creamy!</p><br /><p>- Long-Lasting Scent, tahan lama untuk menemani aktivitasmu<br>- Perfect for Daily Wear, wangi yang pas dan nyaman untuk aktivitas sehari-hari</p><br /><p>Cara Pakai<br>- Semprot pada titik nadi dengan jarak 15-20 cm<br>- Tunggu hingga kering</p> | G4: 1158 | H4: SAFF & Co
A5: 118066 | B5: Velvet Rouge Extrait De Parfum | C5: 5db51d092023815654e4cc93 | D5: 75000 | E5: 4.8662485 | F5: <p>Scarlett Whitening Eau De Parfum 30ml<br>Scarlett Whitening Eau De Parfum a Perfection untuk berikan kesegaran dan keharuman mewah dalam setiap semprotan dengan kemasan yang Ready To Go cocok untuk temani harimu, mudah dibawa kemana pun dan kapan pun tanpa takut pecah! dengan wangi yang mewah<br>Luxurious Scent with Affordable Price.</p> | G5: 235 | H5: Scarlett Whitening
A6: 124504 | B6: Cotton Hug Extrait De Parfum | C6: 5db51d092023815654e4cc93 | D6: 67500 | E6: 4.8509666 | F6: <p>Jenis Aroma : Woody Powdery <br><br>Cotton Hug menggambarkan sosok yang tenang, lembut, dan elegan tanpa usaha berlebihan. Aroma bersih dari aldehyde, orange, dan sentuhan coconut membuka kesan fresh yang menenangkan, seperti pakaian hangat yang baru dijemur di bawah matahari pagi. Di tengahnya, perpaduan muguet, violet, dan orchid menghadirkan keanggunan feminin yang lembut. Lapisan akhir moss, sandalwood, musk, dan amber memberi sentuhan hangat dan powdery, membungkus lembut seperti pelukan penuh ketenangan. <br><br>Top Notes : Aldehyde, Ylang Ylang, Orange, Coconut, Berries <br>Heart Notes : Muguet, Rose, Orange Flower, Violet, Orchid <br>Bottom Notes : Moss, Sandalwood, Musk, Amber, Tonka</p> | G6: 92 | H6: Scarlett Whitening
A7: 113698 | B7: Cloud Mist - Annabel Lee | C7: 60d4e2c6443396b9504d4beb | D7: 199000 | E7: 4.7735507 | F7: <p>Annabel Lee menangkap nostalgia pertemuan awal, menggemakan keindahan mentah dan keajaiban tak terucapkan dari hati muda yang terjalin dalam kepolosan cinta pertama. Dari luapan emosi yang memusingkan hingga kepedihan kenaifan yang manis, syair-syair ini membisikkan kisah dramatis tentang awal yang lembut dan penemuan yang menggetarkan hati.</p><p></p><p>CHARACTER : Floral, Fruity, Gourmand</p><p>Top Notes | Iced lychee tea, Pear, Petalia</p><p>Middle Notes | Akigalawood, Roseraie de l'Hay, Cashmeran </p><p>Dry-down Notes | Crème de framboise, Amber "</p> | G7: 657 | H7: SAFF & Co
A8: 107813 | B8: Xocolatl - Extrait De Parfum | C8: 60d4e2c6443396b9504d4beb | D8: 349000 | E8: 4.8445251 | F8: <p>Parfum gourmand yang terinspirasi dari hot chocolate pertama, dipadukan mandarin manis dan heliotrope creamy yang playful.</p><br /><p>NOTES<br>TOP: Sweet Mandarin<br>MID: Heliotrope<br>BASE: Creamy Gourmand Notes</p><br /><p>Cocok buat kamu yang suka parfum chocolate gourmand yang sweet dan creamy!</p><br /><p>- Long-Lasting Scent, tahan lama untuk menemani aktivitasmu<br>- Perfect for Daily Wear, wangi yang pas dan nyaman untuk aktivitas sehari-hari</p><br /><p>Cara Pakai<br>- Semprot pada titik nadi dengan jarak 15-20 cm<br>- Tunggu hingga kering</p> | G8: 495 | H8: SAFF & Co
A9: 101486 | B9: Body Mist - Crème Canele | C9: 62bbfd4abd4201d78fc0e8f5 | D9: 34000 | E9: 4.6795062 | F9: <p>Crème Canele menghadirkan aroma vanilla yang manis dan addictive, berpadu dengan karakter cheerful, indulging, dan sensual modern.</p> <p>NOTES<br>TOP: Orange Blossom, Pear, Pink Pepper<br>MID: Jasmine, Rose, Freesia<br>BASE: Vanilla, Patchouli, Cedar, Musk</p> <p>Cocok buat kamu yang suka parfum warm vanilla yang sweet, spicy, dan gourmand!</p> <p>- Long-Lasting Scent, tahan lama untuk menemani aktivitasmu<br>- Perfect for Daily Wear, wangi yang pas dan nyaman untuk aktivitas sehari-hari</p> <p>Cara Pakai<br>- Semprot pada titik nadi dengan jarak 15-20 cm<br>- Tunggu hingga kering</p> | G9: 619 | H9: Bonavie
A10: 124503 | B10: Sweetie Love Extrait De Parfum | C10: 5db51d092023815654e4cc93 | D10: 67500 | E10: 4.9111111 | F10: <p>Jenis Aroma : Fruity Floral<br><br>Sweetie Love memancarkan kepribadian yang ceria, youthful, dan penuh cinta. Dibuka dengan aroma manis caramel, segarnya apple dan green pear, menghadirkan kesan playful sejak semprotan pertama. Di tengahnya, perpaduan magnolia, rose, dan sedikit licorice memberi sentuhan feminin yang lembut dan memikat. Ditutup dengan musk dan amber yang hangat, meninggalkan jejak manis yang romantis dan bertahan lama, semanis momen jatuh cinta pertama kali.<br><br>Top Notes : Caramel, Apple, Green Pear<br>Heart Notes : Licorice, Magnolia, Rose<br>Bottom Notes : Musk, Amber</p> | G10: 64 | H10: Scarlett Whitening
A11: 109448 | B11: Scarlett Eau De Parfume Sweet Memories | C11: 5db51d092023815654e4cc93 | D11: 75000 | E11: 4.8341443 | F11: <p>Scarlett Parfume Sweet Memories EDP 30 ml<br>Scarlett Whitening Eau De Parfum Sweet Memories Untuk berikan kesegaran dan keharuman mewah dalam setiap semprotan dengan kemasan yang Ready To Go cocok untuk temani harimu, mudah dibawa kemana pun dan kapan pun tanpa takut pecah! dengan wangi Amber Fougere yang menjadikan parfum ini mempunyai wangi yang mewah.<br><br>Luxurious Scent with Affordable Price.<br>Gender - Unisex | Woman<br>Top Notes - Egyptian Balsam, Grapefruit, Damask Rose<br>Middle Notes - Vanilla, Honeysuckle, Jasmine, Peach<br>Base Notes - Musky, Cashmeran, Amber</p> | G11: 163 | H11: Scarlett Whitening
A12: 109449 | B12: Scarlett Eau De Parfume Dreamy | C12: 5db51d092023815654e4cc93 | D12: 75000 | E12: 4.8687235 | F12: <p>Scarlett Parfume Dreamy EDP 30 ml<br>Scarlett Whitening Eau De Parfum Dreamy Untuk berikan kesegaran dan keharuman mewah dalam setiap semprotan dengan kemasan yang Ready To Go cocok untuk temani harimu, mudah dibawa kemana pun dan kapan pun tanpa takut pecah! dengan wangi floral white Floral Ambery yang menjadikan parfum ini mempunyai wangi yang mewah.<br><br>Luxurious Scent with Affordable Price.<br>Gender - Unisex | Woman<br>Top Notes - Bergamot, Mandarin, Ginger, Pear<br>Middle Notes - Jasmine, Tuberose, Orange Flower, Gourmand<br>Base Notes - Amber Dry, Cashmeran, Heliotrope, Vanilla</p> | G12: 182 | H12: Scarlett Whitening
A13: 114830 | B13: Mykonos Satin Blanc | C13: 66fba216e8005543698af0d8 | D13: 379000 | E13: 4.8845093 | F13: <p>Parfum yang menghadirkan kesan clean dan modern lewat fresh woody aromatic notes yang elegan.</p> <p>NOTES<br>TOP: Bergamot, Black Pepper, Green Apple<br>MIDDLE: Cedar Wood, Jasmine Tea, Floral Bouquet, Aquatic Notes<br>BASE: White Amber, Tonka Bean, Vanilla</p> <p>Cocok buat kamu yang suka parfum fresh dan elegant!</p> <p>- Long-Lasting Scent, tahan lama untuk menemani aktivitasmu<br>- Perfect for Daily Wear, wangi yang pas dan nyaman untuk aktivitas sehari-hari</p> <p>Cara Pakai<br>- Semprot pada titik nadi dengan jarak 15-20 cm<br>- Tunggu hingga kering</p> | G13: 206 | H13: Mykonos
... A300: 117726 | B300: CARESO Eau De Toilette Honey Blush | C300: 5f5640bc311107db64724988 | D300: 82000 | E300: 4.7272727 | F300: <p><em>Honey varies in smell depending on the environment and which flowers the bees pollinated to produce nectar. Every spray is delicate and gives an interesting combination that truly enhance the senses.<br>The perfume will last upto 6 hours.</em></p> | G300: 23 | H300: Careso
A301: 125426 | B301: IN THE MOOD FOR x IGNIO Bundle Set [Crush & Eclipse] | C301: 667d3cc467565050b7424bc9 | D301: 248000 | E301: 0 | G301: 0 | H301: In The Mood For
A302: 120630 | B302: MERCREDI LAIT EDP | C302: 654070018fac4010da648abf | D302: 158000 | E302: 0 | F302: <p>Parfum fruity yang ringan, juicy, dan manis seperti permen melon dalam udara sejuk.</p> <p>NOTES: Melon Candy, Cool Air Accord, dan Soft Sweet Notes.</p> <p>Cocok buat kamu yang menyukai aroma buah manis yang cheerful, ringan, dan mudah dipakai.</p> <p>- Juicy Melon Scent, aroma melon terasa segar dan menyenangkan<br>- Cooling Impression, nuansa udara sejuk membuat aroma tidak terasa berat<br>- Soft Sweet Trail, manisnya lembut namun tetap addictive<br>- Long-Lasting Scent, tahan lama untuk menemani aktivitasmu</p> <p>Cara Pakai:<br>- Semprotkan secukupnya ke titik nadi dari jarak 10–20 cm</p> | G302: 0 | H302: Mercredi
A303: 114831 | B303: Mykonos Sparkling Rose | C303: 66fba216e8005543698af0d8 | D303: 99000 | E303: 4 | F303: <p>Parfum yang menghadirkan kilau rose yang romantis dengan sentuhan red berries, plum, dan warm woody notes.</p> <p>NOTES<br>TOP: Damask Rose, Orange, Geranium<br>MIDDLE: May Rose, Sparkling Red Berries, Plum, Sandalwood<br>BASE: Patchouli, Amber, Guaiac Wood, Musk</p> <p>Cocok buat kamu yang suka parfum rose floral, fruity, dan elegant!</p> <p>- Long-Lasting Scent, tahan lama untuk menemani aktivitasmu<br>- Perfect for Daily Wear, wangi yang pas dan nyaman untuk aktivitas sehari-hari</p> <p>Cara Pakai<br>- Semprot pada titik nadi dengan jarak 15-20 cm<br>- Tunggu hingga kering</p> | G303: 2 | H303: Mykonos
A304: 123468 | B304: Rose Moss Extrait de Parfum | C304: 62fb16f36d42e66ec212086f | D304: 329000 | E304: 0 | F304: <p>Parfum yang menggambarkan mawar dari taman rahasia setelah hujan, floral, green, dan penuh misteri.</p> <p>NOTES<br>TOP: Blackcurrant, Cardamom, Chamomile, Lavandin<br>MID: Rose, Jasmine, Neroli, Petitgrain, Geranium, Clove<br>BASE: Moss, Benzoin, Fir</p> <p>Cocok buat kamu yang suka parfum rose green yang earthy dan elegant!</p> <p>- Long-Lasting Scent, tahan lama untuk menemani aktivitasmu<br>- Perfect for Daily Wear, nyaman dipakai untuk aktivitas sehari-hari</p> <p>Cara Pakai<br>- Semprot pada titik nadi dengan jarak 15-20 cm<br>- Tunggu hingga kering</p> | G304: 0 | H304: Verites
A305: 114843 | B305: Mykonos Hawaiian Crush | C305: 66fba216e8005543698af0d8 | D305: 99000 | E305: 4.4398148 | F305: <p>Parfum yang menghadirkan sensasi fruity tea floral dengan sentuhan lychee, black tea, dan warm musky notes.</p> <p>NOTES<br>TOP: Lychee, Red Fruits, Black Tea<br>MIDDLE: Rose, Lily of the Valley, Lychee, Black Tea<br>BASE: Amber, Patchouli, Musk, Incense</p> <p>Cocok buat kamu yang suka parfum fruity dan elegant!</p> <p>- Long-Lasting Scent, tahan lama untuk menemani aktivitasmu<br>- Perfect for Daily Wear, wangi yang pas dan nyaman untuk aktivitas sehari-hari</p> <p>Cara Pakai<br>- Semprot pada titik nadi dengan jarak 15-20 cm<br>- Tunggu hingga kering</p> | G305: 9 | H305: Mykonos
A306: 114797 | B306: Mykonos Paradise EDP | C306: 66fba216e8005543698af0d8 | D306: 179000 | E306: 4.6666667 | F306: <p>Parfum yang menghadirkan suasana paradise yang cerah lewat coconut, fruity notes, dan sentuhan floral tropis.</p> <p>NOTES<br>TOP: Coconut, Mandarin Orange, Pear, Pineapple<br>MIDDLE: Frangipani, Jasmine, Lily<br>BASE: Amber, Vanilla, Woody Notes</p> <p>Cocok buat kamu yang suka parfum tropical, creamy, dan fruity floral!</p> <p>- Long-Lasting Scent, tahan lama untuk menemani aktivitasmu<br>- Perfect for Daily Wear, wangi yang pas dan nyaman untuk aktivitas sehari-hari</p> <p>Cara Pakai<br>- Semprot pada titik nadi dengan jarak 15-20 cm<br>- Tunggu hingga kering</p> | G306: 3 | H306: Mykonos
A307: 111794 | B307: Sunset Hour | C307: 662b56b473a9ec785fc0b744 | D307: 249000 | E307: 5 | F307: <p>Parfum yang menangkap momen golden hour lewat aroma orange, vanilla, dan musk yang manis dan comforting.</p><br /><p>NOTES<br>TOP: Bergamot, Orange, Sugar<br>MIDDLE: Vanilla, Licorice, Violet Blossoms<br>BASE: Sandalwood, Musk, Star Anise </p> <p>Cocok buat kamu yang suka parfum sweet, warm, dan intoxicating!</p> <p>- Long-Lasting Scent, tahan hingga 8 jam<br>- Perfect for Daily Wear, wangi yang pas dan nyaman untuk aktivitas sehari-hari</p> <p>Cara Pakai<br>- Semprot pada titik nadi dengan jarak 15-20 cm<br>- Tunggu hingga kering</p> | G307: 1 | H307: YN Perfumery
A308: 106058 | B308: Perfume Mist Lily & Suede | C308: 63f33afa031c4c49121df81c | D308: 95000 | E308: 4.382716 | F308: <p>Lily &amp; Suede menghadirkan pesona feminin yang lembut dan romantis, terinspirasi dari cinta pertama yang murni.</p><br /><p>NOTES<br>TOP: Lily of the Valley<br>MID: Amber<br>BASE: Apple Zest</p> <p>Cocok buat kamu yang suka parfum floral feminine yang soft, romantic, dan charming!</p> <p>- Long-Lasting Scent, tahan lama untuk menemani aktivitasmu<br>- Perfect for Daily Wear, wangi yang pas dan nyaman untuk aktivitas sehari-hari</p> <p>Cara Pakai<br>- Semprot pada titik nadi dengan jarak 15-20 cm<br>- Tunggu hingga kering</p> | G308: 27 | H308: Elmer
A309: 117716 | B309: CARESO Eau De Toilette Spring In New York | C309: 5f5640bc311107db64724988 | D309: 82000 | E309: 4.3333333 | F309: <p><em>The essence of spring! The freshness of ripe Pears combine with the newly bloomed Freesias, balanced by Roses, Ambers, Patchouli and Whitemusk.<br>The perfume will last upto 6 hours.</em></p> | G309: 6 | H309: Careso
A310: 106268 | B310: Scent of Jarte Blank Space Eau De Parfum | C310: 5d3ac2ffa6992471b7c971d6 | D310: 275000 | E310: 4.5757576 | F310: <p>Blank Space membawa nuansa delicacy yang fresh dan sweet, dengan kesan feminin yang membuat aroma terasa memorable.</p><br /><p>NOTES<br>TOP: Mandarin, Blackcurrant, Orange Blossom<br>MID: Pear, Tuberose, Jasmine<br>BASE: Musk, Cedarwood, Vanilla</p><br /><p>Cocok buat kamu yang suka parfum fresh, sweet, feminine, dan elegant!</p> <p>- Long-Lasting Scent, tahan hingga 6–8 jam<br>- Perfect for Daily Wear, wangi yang pas dan nyaman untuk aktivitas sehari-hari</p> <p>Cara Pakai<br>- Semprot pada titik nadi dengan jarak 15-20 cm<br>- Tunggu hingga kering</p> | G310: 11 | H310: Jarte Beauty
A311: 120631 | B311: MERCREDI SOIA EDP | C311: 654070018fac4010da648abf | D311: 158000 | E311: 0 | F311: <p>Parfum creamy dan hangat yang terasa lembut seperti pagi santai dengan pakaian ternyaman.</p> <p>NOTES: Creamy Accord, Nutty Notes, Earthy Notes, dan Soft Musk.</p> <p>Cocok buat kamu yang menyukai aroma creamy, nutty, earthy, dan comforting.</p> <p>- Creamy Warm Scent, aroma lembut memberi kesan cozy<br>- Nutty-Earthy Character, perpaduan nutty dan earthy terasa unik serta menenangkan<br>- Soft Skin-Like Trail, jejak aromanya lembut dan dekat dengan kulit<br>- Long-Lasting Scent, tahan lama untuk menemani aktivitasmu</p> <p>Cara Pakai:<br>- Semprotkan secukupnya ke titik nadi dari jarak 10–20 cm</p> | G311: 0 | H311: Mercredi
A312: 124844 | B312: On A Date Eau De Parfum | C312: 62fb16f36d42e66ec212086f | D312: 239000 | E312: 4.5 | F312: <p>Parfum yang dibuat untuk meninggalkan kesan manis, elegan, dan memorable seperti malam yang sempurna.</p> <p>NOTES<br>TOP: Strawberry, Blackcurrant, Lychee, Mint<br>MID: Cinnamon, Orange Blossom, Rose<br>BASE: Edible Notes, Dry Woods, Smoky Notes</p> <p>Cocok buat kamu yang suka parfum fruity rose yang sweet dan memorable!</p> <p>- Long-Lasting Scent, tahan lama untuk menemani aktivitasmu<br>- Perfect for Daily Wear, nyaman dipakai untuk aktivitas sehari-hari</p> <p>Cara Pakai<br>- Semprot pada titik nadi dengan jarak 15-20 cm<br>- Tunggu hingga kering</p> | G312: 2 | H312: Verites
A313: 125974 | B313: Out West - A.M | C313: 630c79bfa09d276df7478c18 | D313: 579000 | E313: 4 | F313: <p>Parfum yang dirancang untuk merekah dalam cahaya pagi, dengan pink pepper, lemon, jahe, resin hangat, dan leather yang berlapis.</p> <p>NOTES<br>TOP: Pink Pepper CO₂ LMR, Lemon Oil Spain LMR, Jahe<br>MIDDLE: Cypriol, Balsamic<br>BASE: Cedarwood, Patchouli Oil Indonesia LMR, Nuansa Leather</p> <p>Cocok buat kamu yang suka parfum woody dan leathery!</p> <p>- Long-Lasting Scent, tahan lama untuk menemani aktivitasmu<br>- Perfect for Daily Wear, wangi yang pas dan nyaman untuk aktivitas sehari-hari</p> <p>Cara Pakai<br>- Semprot pada titik nadi dengan jarak 15-20 cm<br>- Tunggu hingga kering</p> | G313: 1 | H313: Alchemist Fragrance
... A350: 125402 | B350: IN THE MOOD FOR x IGNIO Bundle Set [Date & Eclipse] | C350: 667d3cc467565050b7424bc9 | D350: 248000 | E350: 0 | F350: <p><strong>His &amp; Hers<br>Couple Bundles </strong><br><br><strong>IN THE MOOD FOR - DATE:<br></strong>Aroma mewah dari Eropa yang membawamu pada memori kencan pertama yang manis dan romantis.<br><br>Scent Notes: <br>Top: Rose, Peach, Apple<br>Middle: Bergamot, Tuberose, Jasmine<br>Base: Woods, Ambers, Vanilla<br><br><strong>IGNIO - Eclipse:<br></strong>Scent Notes: <strong><br></strong>Top: Juniper Berry, Lemon, Black Pepper<br>Middle: Grass, Elemi, Geranium<br>Base: Amber, Wood, Musk</p> | G350: 0 | H350: In The Mood For
A351: 125427 | B351: IN THE MOOD FOR x IGNIO Bundle Set [Crush & Flame] | C351: 667d3cc467565050b7424bc9 | D351: 248000 | E351: 0 | G351: 0 | H351: In The Mood For
A352: 123473 | B352: Oud Rages Extrait de Parfum | C352: 62fb16f36d42e66ec212086f | D352: 329000 | E352: 0 | F352: <p>Parfum yang menggambarkan sisi oud yang liar, bold, dan berani mendobrak aturan.</p> <p>NOTES<br>TOP: Nutmeg, Saffron, Lavender<br>MID: Leather, Tobacco, Oud<br>BASE: Patchouli, Moss, Musk, Oriental Woody</p> <p>Cocok buat kamu yang suka parfum oud leather yang intense dan powerful!</p> <p>- Long-Lasting Scent, tahan lama untuk menemani aktivitasmu<br>- Perfect for Daily Wear, nyaman dipakai untuk aktivitas sehari-hari</p> <p>Cara Pakai<br>- Semprot pada titik nadi dengan jarak 15-20 cm<br>- Tunggu hingga kering</p> | G352: 0 | H352: Verites
A353: 109392 | B353: Invigorating Waterfall Eau de Toilette | C353: 657ad93e28f41e975c8a966c | D353: 82900 | E353: 5 | F353: <p>Kahf Invigroating Waterfall Eau de Toilette merupakan parfum dengan paduan aroma Aquatic dan Floral yang memberikan kesegaran nuansa air terjun. Dilengkapi dengan aroma Citrus dan Aromatik membawa kita ke dalam atmosfir yang penuh semangat selayaknya air memberikan energi pada setiap kehidupan.<br>&nbsp;<br>&nbsp;Keunggulan dari item ini adalah:<br>&nbsp;1. Aroma yang memberikan kesegaran<br>&nbsp;2. Tahan hingga 12 jam<br>&nbsp;3. Aroma khas yang memberikan kesegaran alam<br>&nbsp;4. Cocok untuk pemakaian sehari-hari<br></p> | G353: 2 | H353: Kahf
A354: 108423 | B354: De Club Eau De Parfum | C354: 62fb16f36d42e66ec212086f | D354: 269000 | E354: 4.7142857 | F354: <p>Parfum yang menggambarkan malam eksklusif yang bebas, elegan, dan penuh pesona tanpa perlu banyak usaha.</p> <p>NOTES<br>TOP: Lavandin, Clary Sage<br>MID: Virginia Cedarwood<br>BASE: Vetiver</p> <p>Cocok buat kamu yang suka parfum aromatic woody yang masculine dan refined!</p> <p>- Long-Lasting Scent, tahan lama untuk menemani aktivitasmu<br>- Perfect for Daily Wear, nyaman dipakai untuk aktivitas sehari-hari</p> <p>Cara Pakai<br>- Semprot pada titik nadi dengan jarak 15-20 cm<br>- Tunggu hingga kering</p> | G354: 7 | H354: Verites
A355: 106054 | B355: Perfume Mist Pear & Freesia | C355: 63f33afa031c4c49121df81c | D355: 95000 | E355: 4.3333333 | F355: <p>Pear &amp; Freesia menghadirkan kesegaran crisp pear dalam buket freesia putih dengan sentuhan patchouli yang halus, memberi kesan elegan namun chic.</p><br /><p>NOTES<br>TOP: Crisp Pear<br>MID: Freesia<br>BASE: Patchouli</p> <p>Cocok buat kamu yang suka parfum fruity floral yang fresh, elegant, dan effortless!</p> <p>- Long-Lasting Scent, tahan lama untuk menemani aktivitasmu<br>- Perfect for Daily Wear, wangi yang pas dan nyaman untuk aktivitas sehari-hari</p> <p>Cara Pakai<br>- Semprot pada titik nadi dengan jarak 15-20 cm<br>- Tunggu hingga kering</p> | G355: 13 | H355: Elmer
A356: 124830 | B356: Honey Bee Gentle Mist | C356: 62fb16f36d42e66ec212086f | D356: 209000 | E356: 5 | F356: <p>Floral, Fruity<br>Top : Mandarin, Raspberry, Pear<br>Mid : Jasmine, Gardenia, Orange Blossom<br>Dry : Patchouli, Amber, White Honey<br><br>“Honey Bee” menangkap suasana taman yang disinari matahari, penuh bunga bermekaran dan udara manis yang hangat. Dibuka dengan mandarin, raspberry, dan pear yang juicy dan cerah. Di bagian tengah, jasmine, gardenia, dan orange blossom membentuk bouquet floral yang lush dan hidup.<br><br>Di akhir, patchouli, amber, dan white honey menjadi bintang utama—memberikan sentuhan manis, creamy, dan hangat yang memeluk kulit dengan lembut. “Honey Bee” cocok untuk kamu yang mencintai aroma floral manis alami dan ingin terasa hangat sepanjang hari.</p> | G356: 1 | H356: Verites
A357: 124827 | B357: Cake Me Away Gentle Mist | C357: 62fb16f36d42e66ec212086f | D357: 209000 | E357: 0 | F357: <p>Top : Pear, Berry, Peach, Mandarin<br>Mid : Jasmine/ White Floral, Lily of the Valley<br>Dry : Vanilla, Amber, Musk<br><br>“Cake Me Away” adalah wewangian manis dan lezat yang menangkap kesenangan menikmati dessert favoritmu. Aromanya dibuka dengan perpaduan buah yang juicy—pear, berry, peach, dan mandarin—memberikan kesan cerah dan menggugah selera, seperti gigitan pertama kue dengan frosting sempurna.<br><br>Di bagian tengah, hadir sentuhan floral lembut dari jasmine dan lily of the valley yang menyeimbangkan rasa manisnya. Penutupnya hangat dan menenangkan, dengan vanilla creamy, amber yang rich, dan musk lembut yang membalut kulit dengan aroma manis yang cozy dan tahan lama.<br><br>“Cake Me Away” pas untuk kamu yang suka menikmati momen-momen manis dan ingin wewangian yang terasa senyaman sepotong kue.</p> | G357: 1 | H357: Verites
A358: 111816 | B358: Chillin Baby | C358: 655dc43d5d8272b99f510b3b | D358: 129000 | E358: 4 | F358: <p>Parfum yang menghadirkan vibes rich baby dengan aroma floral sweet dan musky ambery yang bikin mood naik lagi.</p> <p>NOTES<br>TOP: Peach, Apple, Melon<br>MIDDLE: Mimosa, Tuberose, Freesia, Jasmine, Ylang-Ylang<br>BASE: Sandalwood, Musk, Oakmoss </p> <p>Cocok buat kamu yang suka parfum floral fruity!</p> <p>- Long-Lasting Scent, tahan lama untuk menemani aktivitasmu<br>- Perfect for Daily Wear, wangi yang pas dan nyaman untuk aktivitas sehari-hari</p> <p>Cara Pakai<br>- Semprot pada titik nadi dengan jarak 15-20 cm<br>- Tunggu hingga kering</p> | G358: 3 | H358: Onix
A359: 109395 | B359: Revered Oud Eau de Toilette | C359: 657ad93e28f41e975c8a966c | D359: 82900 | E359: 4.5555556 | F359: <p>Kahf Revered Oud Eau de Toilette merupakan parfum yang menghadirkan aroma Oud dan Amber yang lekat dengan warisan tradisi budaya. Hint Gourmand dan Vanilla membawa kembali manisnya memori terdahulu. Sentuhan awal Rose membuat kita semakin cinta pada tempat kita bermula.<br>&nbsp;<br>&nbsp;Keunggulan dari item ini adalah:<br>&nbsp;1. Aroma yang memberikan kesan kasual<br>&nbsp;2. Tahan hingga 12 jam<br>&nbsp;3. Aroma khas yang memberikan kesegaran alam<br>&nbsp;4. Cocok untuk pemakaian sehari-hari<br></p> | G359: 3 | H359: Kahf
A360: 117775 | B360: Tahiti Sunrise | C360: 678f22b3bf9a94d16f30d103 | D360: 229000 | E360: 3.3333333 | F360: <p>Parfum fresh tropical yang menghadirkan suasana sunrise di Tahiti yang cerah dan menenangkan.</p> <p>NOTES<br>TOP: Coconut, Fruity Notes<br>MID: Sea Salt, Solar Notes<br>BASE: Vanilla, Musk, Amber</p> <p>Cocok buat kamu yang suka parfum fresh tropical dengan karakter segar, cerah, dan uplifting!</p> <p>- Long-Lasting Scent, tahan lama untuk menemani aktivitasmu<br>- Fresh Uplifting Aroma, memberikan energi positif sepanjang hari<br>- Perfect for Evening &amp; Formal Occasion, cocok dipakai saat malam hari atau acara formal</p> <p>Cara Pakai<br>- Semprot pada titik nadi dengan jarak 15-20 cm<br>- Tunggu hingga kering</p> | G360: 1 | H360: Alt perfumery
A361: 106057 | B361: Perfume Mist Oakwood & Leather | C361: 63f33afa031c4c49121df81c | D361: 95000 | E361: 4.5 | F361: <p>Oakwood &amp; Leather melambangkan karisma dengan perpaduan maskulin antara kayu dan vetiver yang memikat setiap momen menjadi kenangan abadi.</p><br /><p>NOTES<br>TOP: Oakwood, Leather<br>MID: Geranium, Vetiver<br>BASE: Tonka Bean</p> <p>Cocok buat kamu yang suka parfum woody masculine yang charismatic, warm, dan refined!</p> <p>- Long-Lasting Scent, tahan lama untuk menemani aktivitasmu<br>- Perfect for Daily Wear, wangi yang pas dan nyaman untuk aktivitas sehari-hari</p> <p>Cara Pakai<br>- Semprot pada titik nadi dengan jarak 15-20 cm<br>- Tunggu hingga kering</p> | G361: 6 | H361: Elmer
A362: 124832 | B362: Poetry & Pastry Gentle Mist | C362: 62fb16f36d42e66ec212086f | D362: 209000 | E362: 0 | F362: <p>Fruity, Floral, Musk<br>Top : Citrus peel, Milk Chocolate, Caramelized Pear Note<br>Mid : Lily of the Valley, Orange Blossom, Antillone*<br>Dry : Coconut milk, Sandalwood cream, Precious Musks<br><br>“Poetry &amp; Pastry” adalah wewangian charming yang memadukan gourmand dan floral, terinspirasi dari suasana kafe yang cozy. Dibuka dengan citrus peel yang segar, berpadu dengan milk chocolate dan caramelized pear yang manis dan menggoda.<br><br>Bagian tengah menghadirkan lily of the valley dan orange blossom yang lembut, dengan sentuhan Antillone* yang memberi karakter unik. Penutupnya creamy dan comforting, dengan coconut milk, sandalwood cream, dan soft musk yang terasa hangat dan mewah. Cocok untuk kamu yang menyukai manisnya hidup dengan sentuhan elegan.</p> | G362: 0 | H362: Verites
...

Sheet top10

Sheet brandmetrics
A1: brand_id | B1: brand_name | C1: product_count | D1: total_reviews | E1: average_rating | F1: minimum_price | G1: maximum_price | H1: average_price | I1: reviews_per_product | J1: products_4_5_plus | K1: products_with_rating | L1: pct_products_4_5_plus | Q1: {={brandmetrics!B1:B55,brandmetrics!C1:C55,brandmetrics!E1:E55,brandmetrics!D1:D55}} -> brand_name | R1: product_count | S1: average_rating | T1: total_reviews
A2: 5d3ac2ffa6992471b7c971d6 | B2: Jarte Beauty | C2: 19 | D2: 93 | E2: 3.3849369 | F2: 189000 | G2: 855000 | H2: 367052.63 | I2: 4.8947368 | J2: 10 | K2: 19 | L2: 52.631579 | Q2: Jarte Beauty | R2: 19 | S2: 3.3849369 | T2: 93
A3: 5d3ac307a6992471b7c97a2d | B3: BLP Beauty | C3: 4 | D3: 74 | E3: 4.7617322 | F3: 289000 | G3: 289000 | H3: 289000 | I3: 18.5 | J3: 4 | K3: 4 | L3: 100 | Q3: BLP Beauty | R3: 4 | S3: 4.7617322 | T3: 74
A4: 5d3ac307a6992471b7c97b2f | B4: Rollover Reaction | C4: 2 | D4: 12 | E4: 3.6666667 | F4: 169000 | G4: 179000 | H4: 174000 | I4: 6 | J4: 1 | K4: 2 | L4: 50 | Q4: Rollover Reaction | R4: 2 | S4: 3.6666667 | T4: 12
A5: 5d3ac307a6992471b7c97b76 | B5: Wardah | C5: 1 | D5: 609 | E5: 4.416181 | F5: 43500 | G5: 43500 | H5: 43500 | I5: 609 | J5: 0 | K5: 1 | L5: 0 | Q5: Wardah | R5: 1 | S5: 4.416181 | T5: 609
A6: 5d3ac307a6992471b7c97bab | B6: Jacquelle Beaute | C6: 6 | D6: 19 | E6: 3.8222222 | F6: 69000 | G6: 288000 | H6: 161166.67 | I6: 3.1666667 | J6: 3 | K6: 6 | L6: 50 | Q6: Jacquelle Beaute | R6: 6 | S6: 3.8222222 | T6: 19
A7: 5db51d092023815654e4cc93 | B7: Scarlett Whitening | C7: 16 | D7: 1244 | E7: 4.8448113 | F7: 67500 | G7: 75000 | H7: 72656.25 | I7: 77.75 | J7: 16 | K7: 16 | L7: 100 | Q7: Scarlett Whitening | R7: 16 | S7: 4.8448113 | T7: 1244
A8: 5f5640bc311107db64724988 | B8: Careso | C8: 22 | D8: 2604 | E8: 4.6272988 | F8: 54000 | G8: 209000 | H8: 107727.27 | I8: 118.36364 | J8: 18 | K8: 22 | L8: 81.818182 | Q8: Careso | R8: 22 | S8: 4.6272988 | T8: 2604
A9: 60d4e2c6443396b9504d4beb | B9: SAFF & Co | C9: 27 | D9: 8171 | E9: 4.7940261 | F9: 199000 | G9: 349000 | H9: 304555.56 | I9: 302.62963 | J9: 27 | K9: 27 | L9: 100 | Q9: SAFF & Co | R9: 27 | S9: 4.7940261 | T9: 8171
A10: 62bbfd4abd4201d78fc0e8f5 | B10: Bonavie | C10: 16 | D10: 2724 | E10: 4.631903 | F10: 34000 | G10: 115000 | H10: 76625 | I10: 170.25 | J10: 14 | K10: 16 | L10: 87.5 | Q10: Bonavie | R10: 16 | S10: 4.631903 | T10: 2724
A11: 62c7f51270c7e2af7c6ad720 | B11: HMNS | C11: 23 | D11: 5624 | E11: 4.1372498 | F11: 139000 | G11: 525000 | H11: 341826.09 | I11: 244.52174 | J11: 20 | K11: 23 | L11: 86.956522 | Q11: HMNS | R11: 23 | S11: 4.1372498 | T11: 5624
A12: 62fb16f36d42e66ec212086f | B12: Verites | C12: 29 | D12: 379 | E12: 3.2607412 | F12: 209000 | G12: 329000 | H12: 270034.48 | I12: 13.068966 | J12: 20 | K12: 29 | L12: 68.965517 | Q12: Verites | R12: 29 | S12: 3.2607412 | T12: 379
A13: 630c79bfa09d276df7478c18 | B13: Alchemist Fragrance | C13: 8 | D13: 783 | E13: 3.9195472 | F13: 199000 | G13: 679000 | H13: 337750 | I13: 97.875 | J13: 4 | K13: 8 | L13: 50 | Q13: Alchemist Fragrance | R13: 8 | S13: 3.9195472 | T13: 783
... A46: 6a4cb2ea215496274f7b9d51 | B46: Barsten | C46: 2 | D46: 0 | E46: 0 | F46: 209000 | G46: 209000 | H46: 209000 | I46: 0 | J46: 0 | K46: 2 | L46: 0 | Q46: Barsten | R46: 2 | S46: 0 | T46: 0

Sheet rating
A1: rating | B1: review_count | C1: percentage | E1: rating_group | F1: countgroup
A2: 1 | B2: 15 | C2: 0.049196458 | E2: 1–1.9 | F2: =SUMIF(rating[rating],">=1",rating[review_count])-SUMIF(rating[rating],">=2",rating[review_count]) -> 28
A3: 1.3 | B3: 4 | C3: 0.013119055 | E3: 2–2.9 | F3: =SUMIF(rating[rating],">=2",rating[review_count])-SUMIF(rating[rating],">=3",rating[review_count]) -> 90
A4: 1.7 | B4: 9 | C4: 0.029517875 | E4: 3–3.9 | F4: =SUMIF($A$2:$A$23,">=3",$B$2:$B$23)-SUMIF($A$2:$A$23,">=4",$B$2:$B$23) -> 1210
A5: 2 | B5: 18 | C5: 0.059035749 | E5: 4–4.9 | F5: =SUMIF(rating[rating],">=4",rating[review_count])-SUMIF(rating[rating],">=5",rating[review_count]) -> 10079
A6: 2.3 | B6: 24 | C6: 0.078714333 | E6: 5 | F6: =SUMIF(rating[rating],5,rating[review_count]) -> 19083
A7: 2.5 | B7: 1 | C7: 0.0032797639
A8: 2.7 | B8: 47 | C8: 0.1541489
A9: 3 | B9: 180 | C9: 0.59035749
A10: 3.3 | B10: 301 | C10: 0.98720892
A11: 3.3333333 | B11: 1 | C11: 0.0032797639
A12: 3.5 | B12: 1 | C12: 0.0032797639
A13: 3.6666667 | B13: 2 | C13: 0.0065595277
A14: 3.7 | B14: 724 | C14: 2.374549
A15: 3.8 | B15: 1 | C15: 0.0032797639
A16: 4 | B16: 2230 | C16: 7.3138734
A17: 4.3 | B17: 3186 | C17: 10.449328
A18: 4.3333333 | B18: 8 | C18: 0.026238111
... A23: 5 | B23: 19083 | C23: 62.587734

Sheet brands
A1: brand_id | B1: brand_name | C1: products_count | D1: Column 1
A2: 65b72e108291fedb80cbd999 | B2: AA TEst | C2: =COUNTIF(products!C:C, brands!A2) -> 0 | D2: =IFERROR(__xludf.DUMMYFUNCTION("SUMPRODUCT(COUNTIF(reviews!B:B, FILTER(products!A:A, products!C:C = A2)))"),0.0) -> 0
A3: 630c79bfa09d276df7478c18 | B3: Alchemist Fragrance | C3: =COUNTIF(products!C:C, brands!A3) -> 8 | D3: =IFERROR(__xludf.DUMMYFUNCTION("SUMPRODUCT(COUNTIF(reviews!B:B, FILTER(products!A:A, products!C:C = A3)))"),783.0) -> 783
A4: 678f22b3bf9a94d16f30d103 | B4: Alt perfumery | C4: =COUNTIF(products!C:C, brands!A4) -> 10 | D4: =IFERROR(__xludf.DUMMYFUNCTION("SUMPRODUCT(COUNTIF(reviews!B:B, FILTER(products!A:A, products!C:C = A4)))"),70.0) -> 70
A5: 686f7faa358423a01d1b1f32 | B5: ATSIRI | C5: =COUNTIF(products!C:C, brands!A5) -> 2 | D5: =IFERROR(__xludf.DUMMYFUNCTION("SUMPRODUCT(COUNTIF(reviews!B:B, FILTER(products!A:A, products!C:C = A5)))"),0.0) -> 0
A6: 689c00257493d86323be7038 | B6: Barbie | C6: =COUNTIF(products!C:C, brands!A6) -> 3 | D6: =IFERROR(__xludf.DUMMYFUNCTION("SUMPRODUCT(COUNTIF(reviews!B:B, FILTER(products!A:A, products!C:C = A6)))"),24.0) -> 24
A7: 6a4cb2ea215496274f7b9d51 | B7: Barsten | C7: =COUNTIF(products!C:C, brands!A7) -> 2 | D7: =IFERROR(__xludf.DUMMYFUNCTION("SUMPRODUCT(COUNTIF(reviews!B:B, FILTER(products!A:A, products!C:C = A7)))"),0.0) -> 0
A8: 6492bb87ec4713a4402897b4 | B8: Beauty Secrets | C8: =COUNTIF(products!C:C, brands!A8) -> 7 | D8: =IFERROR(__xludf.DUMMYFUNCTION("SUMPRODUCT(COUNTIF(reviews!B:B, FILTER(products!A:A, products!C:C = A8)))"),278.0) -> 278
A9: 677f9e29bd1dd357b29899bc | B9: BESTIE PINK RUN | C9: =COUNTIF(products!C:C, brands!A9) -> 1 | D9: =IFERROR(__xludf.DUMMYFUNCTION("SUMPRODUCT(COUNTIF(reviews!B:B, FILTER(products!A:A, products!C:C = A9)))"),0.0) -> 0
A10: 6a2942986a9dc81f99a07ab8 | B10: BLACKSTAG | C10: =COUNTIF(products!C:C, brands!A10) -> 6 | D10: =IFERROR(__xludf.DUMMYFUNCTION("SUMPRODUCT(COUNTIF(reviews!B:B, FILTER(products!A:A, products!C:C = A10)))"),0.0) -> 0
A11: 5d3ac307a6992471b7c97a2d | B11: BLP Beauty | C11: =COUNTIF(products!C:C, brands!A11) -> 4 | D11: =IFERROR(__xludf.DUMMYFUNCTION("SUMPRODUCT(COUNTIF(reviews!B:B, FILTER(products!A:A, products!C:C = A11)))"),74.0) -> 74
A12: 684fc0d7d4bf7febcf441ede | B12: BODIBREZE | C12: =COUNTIF(products!C:C, brands!A12) -> 8 | D12: =IFERROR(__xludf.DUMMYFUNCTION("SUMPRODUCT(COUNTIF(reviews!B:B, FILTER(products!A:A, products!C:C = A12)))"),158.0) -> 158
A13: 62bbfd4abd4201d78fc0e8f5 | B13: Bonavie | C13: =COUNTIF(products!C:C, brands!A13) -> 16 | D13: =IFERROR(__xludf.DUMMYFUNCTION("SUMPRODUCT(COUNTIF(reviews!B:B, FILTER(products!A:A, products!C:C = A13)))"),2724.0) -> 2724
A14: 5f5640bc311107db64724988 | B14: Careso | C14: =COUNTIF(products!C:C, brands!A14) -> 22 | D14: =IFERROR(__xludf.DUMMYFUNCTION("SUMPRODUCT(COUNTIF(reviews!B:B, FILTER(products!A:A, products!C:C = A14)))"),2604.0) -> 2604
A15: 67778a892a80de5b41843ff8 | B15: CONSTANT | C15: =COUNTIF(products!C:C, brands!A15) -> 0 | D15: =IFERROR(__xludf.DUMMYFUNCTION("SUMPRODUCT(COUNTIF(reviews!B:B, FILTER(products!A:A, products!C:C = A15)))"),0.0) -> 0
A16: 687f0e912e6e4dd7b8ae25dd | B16: Crusita | C16: =COUNTIF(products!C:C, brands!A16) -> 10 | D16: =IFERROR(__xludf.DUMMYFUNCTION("SUMPRODUCT(COUNTIF(reviews!B:B, FILTER(products!A:A, products!C:C = A16)))"),469.0) -> 469
A17: 696f319a12cb95e5b7ae13b3 | B17: De Antoine | C17: =COUNTIF(products!C:C, brands!A17) -> 10 | D17: =IFERROR(__xludf.DUMMYFUNCTION("SUMPRODUCT(COUNTIF(reviews!B:B, FILTER(products!A:A, products!C:C = A17)))"),9.0) -> 9
A18: 69292226555238423bb4eecf | B18: Earth Love Life | C18: =COUNTIF(products!C:C, brands!A18) -> 5 | D18: =IFERROR(__xludf.DUMMYFUNCTION("SUMPRODUCT(COUNTIF(reviews!B:B, FILTER(products!A:A, products!C:C = A18)))"),13.0) -> 13
A19: 63f33afa031c4c49121df81c | B19: Elmer | C19: =COUNTIF(products!C:C, brands!A19) -> 5 | D19: =IFERROR(__xludf.DUMMYFUNCTION("SUMPRODUCT(COUNTIF(reviews!B:B, FILTER(products!A:A, products!C:C = A19)))"),148.0) -> 148
A20: 65b76e306a21aad7d8a51fd1 | B20: EONA | C20: =COUNTIF(products!C:C, brands!A20) -> 0 | D20: =IFERROR(__xludf.DUMMYFUNCTION("SUMPRODUCT(COUNTIF(reviews!B:B, FILTER(products!A:A, products!C:C = A20)))"),0.0) -> 0
A21: 6259228f6bfc2e5818b86f27 | B21: Esscentials Indonesia | C21: =COUNTIF(products!C:C, brands!A21) -> 0 | D21: =IFERROR(__xludf.DUMMYFUNCTION("SUMPRODUCT(COUNTIF(reviews!B:B, FILTER(products!A:A, products!C:C = A21)))"),0.0) -> 0
A22: 6311def8368f94cfd772b44d | B22: Fordive | C22: =COUNTIF(products!C:C, brands!A22) -> 6 | D22: =IFERROR(__xludf.DUMMYFUNCTION("SUMPRODUCT(COUNTIF(reviews!B:B, FILTER(products!A:A, products!C:C = A22)))"),152.0) -> 152
A23: 62c7f51270c7e2af7c6ad720 | B23: HMNS | C23: =COUNTIF(products!C:C, brands!A23) -> 23 | D23: =IFERROR(__xludf.DUMMYFUNCTION("SUMPRODUCT(COUNTIF(reviews!B:B, FILTER(products!A:A, products!C:C = A23)))"),5624.0) -> 5624
A24: 68cb7c30436c5829a063d777 | B24: IGNIO | C24: =COUNTIF(products!C:C, brands!A24) -> 3 | D24: =IFERROR(__xludf.DUMMYFUNCTION("SUMPRODUCT(COUNTIF(reviews!B:B, FILTER(products!A:A, products!C:C = A24)))"),128.0) -> 128
A25: 667d3cc467565050b7424bc9 | B25: In The Mood For | C25: =COUNTIF(products!C:C, brands!A25) -> 46 | D25: =IFERROR(__xludf.DUMMYFUNCTION("SUMPRODUCT(COUNTIF(reviews!B:B, FILTER(products!A:A, products!C:C = A25)))"),2044.0) -> 2044
A26: 66a9acee27c22fdce5c62563 | B26: ISLAN | C26: =COUNTIF(products!C:C, brands!A26) -> 4 | D26: =IFERROR(__xludf.DUMMYFUNCTION("SUMPRODUCT(COUNTIF(reviews!B:B, FILTER(products!A:A, products!C:C = A26)))"),41.0) -> 41
A27: 65b325069eda6e77244b9aa3 | B27: ISWHITE | C27: =COUNTIF(products!C:C, brands!A27) -> 6 | D27: =IFERROR(__xludf.DUMMYFUNCTION("SUMPRODUCT(COUNTIF(reviews!B:B, FILTER(products!A:A, products!C:C = A27)))"),6.0) -> 6
A28: 5d3ac307a6992471b7c97bab | B28: Jacquelle Beaute | C28: =COUNTIF(products!C:C, brands!A28) -> 6 | D28: =IFERROR(__xludf.DUMMYFUNCTION("SUMPRODUCT(COUNTIF(reviews!B:B, FILTER(products!A:A, products!C:C = A28)))"),19.0) -> 19
A29: 5d3ac2ffa6992471b7c971d6 | B29: Jarte Beauty | C29: =COUNTIF(products!C:C, brands!A29) -> 19 | D29: =IFERROR(__xludf.DUMMYFUNCTION("SUMPRODUCT(COUNTIF(reviews!B:B, FILTER(products!A:A, products!C:C = A29)))"),93.0) -> 93
A30: 657ad93e28f41e975c8a966c | B30: Kahf | C30: =COUNTIF(products!C:C, brands!A30) -> 14 | D30: =IFERROR(__xludf.DUMMYFUNCTION("SUMPRODUCT(COUNTIF(reviews!B:B, FILTER(products!A:A, products!C:C = A30)))"),27.0) -> 27
A31: 639fccbc887ae13b38ea4221 | B31: Kitschy | C31: =COUNTIF(products!C:C, brands!A31) -> 0 | D31: =IFERROR(__xludf.DUMMYFUNCTION("SUMPRODUCT(COUNTIF(reviews!B:B, FILTER(products!A:A, products!C:C = A31)))"),0.0) -> 0
A32: 62cadbc86429fa4da043c7b7 | B32: Lavojoy | C32: =COUNTIF(products!C:C, brands!A32) -> 0 | D32: =IFERROR(__xludf.DUMMYFUNCTION("SUMPRODUCT(COUNTIF(reviews!B:B, FILTER(products!A:A, products!C:C = A32)))"),0.0) -> 0
A33: 658a8e243cca26bc8b2f676b | B33: Layr | C33: =COUNTIF(products!C:C, brands!A33) -> 4 | D33: =IFERROR(__xludf.DUMMYFUNCTION("SUMPRODUCT(COUNTIF(reviews!B:B, FILTER(products!A:A, products!C:C = A33)))"),130.0) -> 130
A34: 6512b419e2ce9e1e8739b219 | B34: Lilith and Eve | C34: =COUNTIF(products!C:C, brands!A34) -> 0 | D34: =IFERROR(__xludf.DUMMYFUNCTION("SUMPRODUCT(COUNTIF(reviews!B:B, FILTER(products!A:A, products!C:C = A34)))"),0.0) -> 0
A35: 5d3ac306a6992471b7c97824 | B35: Luxcrime | C35: =COUNTIF(products!C:C, brands!A35) -> 0 | D35: =IFERROR(__xludf.DUMMYFUNCTION("SUMPRODUCT(COUNTIF(reviews!B:B, FILTER(products!A:A, products!C:C = A35)))"),0.0) -> 0
A36: 654070018fac4010da648abf | B36: Mercredi | C36: =COUNTIF(products!C:C, brands!A36) -> 8 | D36: =IFERROR(__xludf.DUMMYFUNCTION("SUMPRODUCT(COUNTIF(reviews!B:B, FILTER(products!A:A, products!C:C = A36)))"),7.0) -> 7
A37: 690b205bb7ffaa4cb6a4e8a8 | B37: MMRS | C37: =COUNTIF(products!C:C, brands!A37) -> 6 | D37: =IFERROR(__xludf.DUMMYFUNCTION("SUMPRODUCT(COUNTIF(reviews!B:B, FILTER(products!A:A, products!C:C = A37)))"),1.0) -> 1
A38: 610a4baac3617d6f38595620 | B38: Mother of Pearl | C38: =COUNTIF(products!C:C, brands!A38) -> 0 | D38: =IFERROR(__xludf.DUMMYFUNCTION("SUMPRODUCT(COUNTIF(reviews!B:B, FILTER(products!A:A, products!C:C = A38)))"),0.0) -> 0
A39: 66fba216e8005543698af0d8 | B39: Mykonos | C39: =COUNTIF(products!C:C, brands!A39) -> 37 | D39: =IFERROR(__xludf.DUMMYFUNCTION("SUMPRODUCT(COUNTIF(reviews!B:B, FILTER(products!A:A, products!C:C = A39)))"),1283.0) -> 1283
A40: 6979dfc48d450be00450df29 | B40: Nevernot Official | C40: =COUNTIF(products!C:C, brands!A40) -> 11 | D40: =IFERROR(__xludf.DUMMYFUNCTION("SUMPRODUCT(COUNTIF(reviews!B:B, FILTER(products!A:A, products!C:C = A40)))"),16.0) -> 16
...

Sheet products
A1: product_id | B1: product_name | C1: brand_id | D1: price | E1: avg_rating | F1: description
A2: 110247 | B2: HMNS x Tsana Fragrance Mist - Elea | C2: 62c7f51270c7e2af7c6ad720 | D2: 185000 | E2: 4.743803e+16 | F2: <p>Pertama kali kamu bertemu Elea nanti, tutup mata kamu. Kamu akan dengan mudah mengenalinya dari rambut panjangnya, dan wangi bunga magnolianya. Yang cantik &amp; terasa hijau seperti magnolia yang baru saja dipetik.<br>Sebentar setelah kamu di dekatnya, kamu sadar kalau Elea lebih kompleks dari setangkai bunga magnolia. Elea seperti puluhan kombinasi bunga putih yang terikat dengan madu dan minyak biji ambrette. Dia terasa dekat, terasa hangat.<br>Dan untuk sesaat dalam waktu yang panjang, kamu sadar kalau akhirnya..<br>Kamu gak sendirian.<br>[Product Detail]<br>Type: Eau de Toilette<br>Group: White Floral<br>Size: 250 ml<br>Longevity: 2 - 3 hours<br>Sillage: Medium<br>Projection: 1 - 2.5 meters</p>
A3: 117020 | B3: IRAI LEIMA - Extrait de Parfum | C3: 60d4e2c6443396b9504d4beb | D3: 349000 | E3: 4.8344444e+15 | F3: <p>Parfum aquatic yang membawa sensasi udara laut segar, air yang tenang, dan drydown hangat yang terasa lembut di kulit.</p><br /><p>NOTES<br>TOP: Cassis Buds, Dalanghita, Pink Pepper<br>MID: Duchesse de Nemours, Water Iris, Raat ki Rani<br>BASE: Warm Musky Notes</p><br /><p>Cocok buat kamu yang suka parfum aquatic floral yang fresh dan soft!</p><br /><p>- Long-Lasting Scent, tahan lama untuk menemani aktivitasmu<br>- Perfect for Daily Wear, wangi yang pas dan nyaman untuk aktivitas sehari-hari</p><br /><p>Cara Pakai<br>- Semprot pada titik nadi dengan jarak 15-20 cm<br>- Tunggu hingga kering</p>
A4: 98385 | B4: S.O.T.B - Extrait de Parfum | C4: 60d4e2c6443396b9504d4beb | D4: 349000 | E4: 4.857915e+16 | F4: <p>Parfum yang menangkap summer dream: kulit yang sun-kissed, beach breeze, dan suasana tropical yang fun sepanjang hari.</p><br /><p>NOTES<br>TOP: Mandarin<br>MID: Sweet Floral Notes<br>BASE: Vanilla Musk</p><br /><p>Cocok buat kamu yang suka parfum tropical floral yang fresh dan creamy!</p><br /><p>- Long-Lasting Scent, tahan lama untuk menemani aktivitasmu<br>- Perfect for Daily Wear, wangi yang pas dan nyaman untuk aktivitas sehari-hari</p><br /><p>Cara Pakai<br>- Semprot pada titik nadi dengan jarak 15-20 cm<br>- Tunggu hingga kering</p>
A5: 118066 | B5: Velvet Rouge Extrait De Parfum | C5: 5db51d092023815654e4cc93 | D5: 75000 | E5: 4.8662485e+15 | F5: <p>Scarlett Whitening Eau De Parfum 30ml<br>Scarlett Whitening Eau De Parfum a Perfection untuk berikan kesegaran dan keharuman mewah dalam setiap semprotan dengan kemasan yang Ready To Go cocok untuk temani harimu, mudah dibawa kemana pun dan kapan pun tanpa takut pecah! dengan wangi yang mewah<br>Luxurious Scent with Affordable Price.</p>
A6: 124504 | B6: Cotton Hug Extrait De Parfum | C6: 5db51d092023815654e4cc93 | D6: 67500 | E6: 4.8509666e+15 | F6: <p>Jenis Aroma : Woody Powdery <br><br>Cotton Hug menggambarkan sosok yang tenang, lembut, dan elegan tanpa usaha berlebihan. Aroma bersih dari aldehyde, orange, dan sentuhan coconut membuka kesan fresh yang menenangkan, seperti pakaian hangat yang baru dijemur di bawah matahari pagi. Di tengahnya, perpaduan muguet, violet, dan orchid menghadirkan keanggunan feminin yang lembut. Lapisan akhir moss, sandalwood, musk, dan amber memberi sentuhan hangat dan powdery, membungkus lembut seperti pelukan penuh ketenangan. <br><br>Top Notes : Aldehyde, Ylang Ylang, Orange, Coconut, Berries <br>Heart Notes : Muguet, Rose, Orange Flower, Violet, Orchid <br>Bottom Notes : Moss, Sandalwood, Musk, Amber, Tonka</p>
A7: 113698 | B7: Cloud Mist - Annabel Lee | C7: 60d4e2c6443396b9504d4beb | D7: 199000 | E7: 4.7735507e+15 | F7: <p>Annabel Lee menangkap nostalgia pertemuan awal, menggemakan keindahan mentah dan keajaiban tak terucapkan dari hati muda yang terjalin dalam kepolosan cinta pertama. Dari luapan emosi yang memusingkan hingga kepedihan kenaifan yang manis, syair-syair ini membisikkan kisah dramatis tentang awal yang lembut dan penemuan yang menggetarkan hati.</p><p></p><p>CHARACTER : Floral, Fruity, Gourmand</p><p>Top Notes | Iced lychee tea, Pear, Petalia</p><p>Middle Notes | Akigalawood, Roseraie de l'Hay, Cashmeran </p><p>Dry-down Notes | Crème de framboise, Amber "</p>
A8: 107813 | B8: Xocolatl - Extrait De Parfum | C8: 60d4e2c6443396b9504d4beb | D8: 349000 | E8: 4.8445251e+15 | F8: <p>Parfum gourmand yang terinspirasi dari hot chocolate pertama, dipadukan mandarin manis dan heliotrope creamy yang playful.</p><br /><p>NOTES<br>TOP: Sweet Mandarin<br>MID: Heliotrope<br>BASE: Creamy Gourmand Notes</p><br /><p>Cocok buat kamu yang suka parfum chocolate gourmand yang sweet dan creamy!</p><br /><p>- Long-Lasting Scent, tahan lama untuk menemani aktivitasmu<br>- Perfect for Daily Wear, wangi yang pas dan nyaman untuk aktivitas sehari-hari</p><br /><p>Cara Pakai<br>- Semprot pada titik nadi dengan jarak 15-20 cm<br>- Tunggu hingga kering</p>
A9: 101486 | B9: Body Mist - Crème Canele | C9: 62bbfd4abd4201d78fc0e8f5 | D9: 34000 | E9: 4.6795062e+15 | F9: <p>Crème Canele menghadirkan aroma vanilla yang manis dan addictive, berpadu dengan karakter cheerful, indulging, dan sensual modern.</p> <p>NOTES<br>TOP: Orange Blossom, Pear, Pink Pepper<br>MID: Jasmine, Rose, Freesia<br>BASE: Vanilla, Patchouli, Cedar, Musk</p> <p>Cocok buat kamu yang suka parfum warm vanilla yang sweet, spicy, dan gourmand!</p> <p>- Long-Lasting Scent, tahan lama untuk menemani aktivitasmu<br>- Perfect for Daily Wear, wangi yang pas dan nyaman untuk aktivitas sehari-hari</p> <p>Cara Pakai<br>- Semprot pada titik nadi dengan jarak 15-20 cm<br>- Tunggu hingga kering</p>
A10: 124503 | B10: Sweetie Love Extrait De Parfum | C10: 5db51d092023815654e4cc93 | D10: 67500 | E10: 4.9111111e+15 | F10: <p>Jenis Aroma : Fruity Floral<br><br>Sweetie Love memancarkan kepribadian yang ceria, youthful, dan penuh cinta. Dibuka dengan aroma manis caramel, segarnya apple dan green pear, menghadirkan kesan playful sejak semprotan pertama. Di tengahnya, perpaduan magnolia, rose, dan sedikit licorice memberi sentuhan feminin yang lembut dan memikat. Ditutup dengan musk dan amber yang hangat, meninggalkan jejak manis yang romantis dan bertahan lama, semanis momen jatuh cinta pertama kali.<br><br>Top Notes : Caramel, Apple, Green Pear<br>Heart Notes : Licorice, Magnolia, Rose<br>Bottom Notes : Musk, Amber</p>
A11: 109448 | B11: Scarlett Eau De Parfume Sweet Memories | C11: 5db51d092023815654e4cc93 | D11: 75000 | E11: 4.8341443e+15 | F11: <p>Scarlett Parfume Sweet Memories EDP 30 ml<br>Scarlett Whitening Eau De Parfum Sweet Memories Untuk berikan kesegaran dan keharuman mewah dalam setiap semprotan dengan kemasan yang Ready To Go cocok untuk temani harimu, mudah dibawa kemana pun dan kapan pun tanpa takut pecah! dengan wangi Amber Fougere yang menjadikan parfum ini mempunyai wangi yang mewah.<br><br>Luxurious Scent with Affordable Price.<br>Gender - Unisex | Woman<br>Top Notes - Egyptian Balsam, Grapefruit, Damask Rose<br>Middle Notes - Vanilla, Honeysuckle, Jasmine, Peach<br>Base Notes - Musky, Cashmeran, Amber</p>
A12: 109449 | B12: Scarlett Eau De Parfume Dreamy | C12: 5db51d092023815654e4cc93 | D12: 75000 | E12: 4.8687235e+15 | F12: <p>Scarlett Parfume Dreamy EDP 30 ml<br>Scarlett Whitening Eau De Parfum Dreamy Untuk berikan kesegaran dan keharuman mewah dalam setiap semprotan dengan kemasan yang Ready To Go cocok untuk temani harimu, mudah dibawa kemana pun dan kapan pun tanpa takut pecah! dengan wangi floral white Floral Ambery yang menjadikan parfum ini mempunyai wangi yang mewah.<br><br>Luxurious Scent with Affordable Price.<br>Gender - Unisex | Woman<br>Top Notes - Bergamot, Mandarin, Ginger, Pear<br>Middle Notes - Jasmine, Tuberose, Orange Flower, Gourmand<br>Base Notes - Amber Dry, Cashmeran, Heliotrope, Vanilla</p>
A13: 114830 | B13: Mykonos Satin Blanc | C13: 66fba216e8005543698af0d8 | D13: 379000 | E13: 4.8845093e+15 | F13: <p>Parfum yang menghadirkan kesan clean dan modern lewat fresh woody aromatic notes yang elegan.</p> <p>NOTES<br>TOP: Bergamot, Black Pepper, Green Apple<br>MIDDLE: Cedar Wood, Jasmine Tea, Floral Bouquet, Aquatic Notes<br>BASE: White Amber, Tonka Bean, Vanilla</p> <p>Cocok buat kamu yang suka parfum fresh dan elegant!</p> <p>- Long-Lasting Scent, tahan lama untuk menemani aktivitasmu<br>- Perfect for Daily Wear, wangi yang pas dan nyaman untuk aktivitas sehari-hari</p> <p>Cara Pakai<br>- Semprot pada titik nadi dengan jarak 15-20 cm<br>- Tunggu hingga kering</p>
... A99: 126320 | B99: Sahara Mirage Extrait De Parfum | C99: 5db51d092023815654e4cc93 | D99: 67500 | E99: 4.5555556e+15 | F99: <p>Scarlett Whitening Extrait De Parfum by world class perfumer, long-lasting up to 16 hours, and perfect for daily-use.<br><br>Luxurious Scent with Affordable Price!<br><br><strong>Scarlett Whitening Extrait de Parfum SAHARA MIRAGE</strong><br>Gender - Woman <br>Floral + Fruity + Woody<br>Top notes: Passionfruit, Peach<br>Heart Notes: Geranium, Jasmine<br>Bottom Notes: Vetiver, Patchouli, Dry Amber</p>
A100: 122362 | B100: Slavina Fine Fragrance Mist Shooting Star | C100: 67bbeaee630f7e48677f515a | D100: 119000 | E100: 5.0 | F100: <p>Aroma khas manis dari perpaduan berries dan floral. Kombinasi Vanilla dan Musk pada Base noted menciptakan aroma yang lembut dan tahan lama</p>
A101: 122645 | B101: Eclipse Eau De Parfum | C101: 68cb7c30436c5829a063d777 | D101: 149000 | E101: 4.8805031e+15 | F101: <p>Eclipse Eau De Parfum adalah parfum aromatic woody yang fresh dan sophisticated.</p> <p>NOTES<br>TOP: Juniper Berry, Lemon, Black Pepper<br>MID: Grass, Elemi, Geranium<br>BASE: Amber, Wood, Musk</p> <p>Cocok buat kamu yang suka parfum aromatic woody yang fresh, spicy, dan sophisticated!</p> <p>- Long-Lasting Scent, tahan lama untuk menemani aktivitasmu<br>- Perfect for Daily Wear, wangi yang pas dan nyaman untuk aktivitas sehari-hari</p> <p>Cara Pakai<br>- Semprot pada titik nadi dengan jarak 15-20 cm<br>- Tunggu hingga kering</p>
A102: 107812 | B102: Las Pozas - Extrait De Parfum | C102: 60d4e2c6443396b9504d4beb | D102: 349000 | E102: 4.8195876e+15 | F102: <p>Parfum yang membawamu menyusuri hutan tropis yang tenang, saat angin, kicau burung, dan nuansa woody creamy terasa surreal namun grounding.</p> <p>NOTES<br>- Angel’s Trumpet<br>- Forest Accord<br>- Cashmeran<br>- Sumatran Benzoin, Sandalwood</p> <p>Cocok buat kamu yang suka parfum woody creamy yang earthy dan calming!</p> <p>- Long-Lasting Scent, tahan lama untuk menemani aktivitasmu<br>- Perfect for Daily Wear, wangi yang pas dan nyaman untuk aktivitas sehari-hari</p> <p>Cara Pakai<br>- Semprot pada titik nadi dengan jarak 15-20 cm<br>- Tunggu hingga kering</p>
A103: 122644 | B103: Spark Eau De Parfum | C103: 68cb7c30436c5829a063d777 | D103: 149000 | E103: 481981981981982 | F103: <p>Spark Eau De Parfum adalah parfum citrus aquatic yang fresh dan energizing untuk aktivitas sehari-hari.</p> <p>NOTES<br>TOP: Mandarin, Orange<br>MID: Lavender, Aquatic Accord<br>BASE: Patchouli, Red Cedar, Ambrox</p> <p>Cocok buat kamu yang suka parfum citrus fresh yang clean, energetic, dan modern!</p> <p>- Long-Lasting Scent, tahan lama untuk menemani aktivitasmu<br>- Perfect for Daily Wear, wangi yang pas dan nyaman untuk aktivitas sehari-hari</p> <p>Cara Pakai<br>- Semprot pada titik nadi dengan jarak 15-20 cm<br>- Tunggu hingga kering</p>
A104: 108418 | B104: Blooming Amoure Eau De Parfum | C104: 62fb16f36d42e66ec212086f | D104: 269000 | E104: 4.5789474e+15 | F104: <p>Parfum yang menceritakan mekarnya kisah cinta, dari percikan manis yang segar sampai akhir yang comforting.</p> <p>NOTES<br>TOP: Ginger, Carnation, Green Leaves<br>MID: Tuberose, Jasmine<br>BASE: Musk, Sandalwood</p> <p>Cocok buat kamu yang suka parfum floral musky yang romantic dan soft!</p> <p>- Long-Lasting Scent, tahan lama untuk menemani aktivitasmu<br>- Perfect for Daily Wear, nyaman dipakai untuk aktivitas sehari-hari</p> <p>Cara Pakai<br>- Semprot pada titik nadi dengan jarak 15-20 cm<br>- Tunggu hingga kering</p>
A105: 86995 | B105: Troupe - Extrait De Parfum | C105: 60d4e2c6443396b9504d4beb | D105: 249000 | E105: 4.6289683e+15 | F105: <p>Parfum yang menghadirkan kesan fresh dan graceful, dengan bukaan fruity segar yang bertemu floral lembut dan musky amber.</p> <p>NOTES<br>TOP: Mandarin Orange, Pear<br>MID: Rose, Neroli, Freesia<br>BASE: Patchouli, Musk, Amber</p> <p>Cocok buat kamu yang suka parfum fresh floral yang delicate dan graceful!</p> <p>- Long-Lasting Scent, tahan lama untuk menemani aktivitasmu<br>- Perfect for Daily Wear, wangi yang pas dan nyaman untuk aktivitas sehari-hari</p> <p>Cara Pakai<br>- Semprot pada titik nadi dengan jarak 15-20 cm<br>- Tunggu hingga kering</p>
A106: 117552 | B106: Untitled Aroma 02 | C106: 62c7f51270c7e2af7c6ad720 | D106: 385000 | E106: 4.7358491e+15 | F106: <p>Di kolaborasi kedua antara HMNS dan Maliq &amp; D’Essentials, Untitled Aroma 02 ini, kita ingin mengingatkan sesuatu yang mungkin sering terlupakan. Yakni, betapa cantiknya kamu. <br><br>Dengan Absolute Rose yang lembut, berpadu dengan Musk Milk yang menenangkan. Saat keduanya bertemu, terciptalah wangi yang bukan hanya memikat, tapi juga terasa begitu personal.<br><br>Lalu, ada sentuhan kecil dari Anise yang segar, Violet yang menambahkan kelembutan, Orris yang anggun, dan Cashmere yang menyatukan semuanya dalam harmoni sempurna.<br><br>Ketahanan: 4-5 Jam<br>Jejak Aroma: Sedang hingga kuat<br>Proyeksi: 1,5 - 2 meter<br>Jenis: Eau de Parfum (EDP)<br>Kategori Wangi: Floral Musk</p>
A107: 123180 | B107: Project 1945 Bamboe Roencing Perfume | Extrait de Parfum Unisex | C107: 64bf8ffd47133c15bf961d74 | D107: 345000 | E107: 4.7971014e+15 | F107: <p>Bamboe Roencing adalah cerminan tekad hati, persatuan, dan semangat pantang menyerah.<br>Terinspirasi dari bambu runcing - simbol perjuangan rakyat Indonesia - serta filosofi motif Pucuk Rebung dan anyaman bambu yang melambangkan keteguhan dan kekuatan. Bamboe Roencing hadir bukan hanya sebagai aroma, tapi sebagai pengingat akan semangat kita.<br><br>Perpaduan aroma Bergamot, Osmanthus, dan Musk menciptakan karakter wangi yang menyegarkan dan membangkitkan harapan serta keberanian dalam menghadapi hari yang penuh tantangan.</p>
A108: 121443 | B108: Black Love | C108: 687f0e912e6e4dd7b8ae25dd | D108: 189000 | E108: 4.8730159e+15 | F108: <p>Black Love memadukan aroma kopi, vanilla, dan almond pahit yang misterius dan memikat dalam satu semprotan.</p> <p>NOTES<br>- Coffee<br>- Vanilla<br>- Bitter Almond</p> <p>Cocok buat kamu yang suka parfum coffee gourmand yang dark, warm, dan sensual!</p> <p>- Long-Lasting Scent, tahan lama untuk menemani aktivitasmu<br>- Perfect for Daily Wear, wangi yang pas dan nyaman untuk aktivitas sehari-hari</p> <p>Cara Pakai<br>- Semprot pada titik nadi dengan jarak 15-20 cm<br>- Tunggu hingga kering</p>
A109: 121488 | B109: Cuddle Eau De Parfum | C109: 667d3cc467565050b7424bc9 | D109: 99000 | E109: 4.8869561e+15 | F109: <p>Cuddle Eau De Parfum menghadirkan aroma soft musky yang clean dan comforting.</p> <p>NOTES<br>TOP: Aldehydes, Lily<br>MID: Rose, Iris<br>BASE: Musk, Ambrette</p> <p>Cocok buat kamu yang suka parfum soft musky yang clean, powdery, dan comforting!</p> <p>- Long-Lasting Scent, ketahanan medium to high<br>- Perfect for Daily Wear, wangi yang pas dan nyaman untuk aktivitas sehari-hari</p> <p>Cara Pakai<br>- Semprot pada titik nadi dengan jarak 15-20 cm<br>- Tunggu hingga kering</p>
A110: 107234 | B110: Healing Trail | C110: 6510fae507d9f80342bc6d05 | D110: 299000 | E110: 4.6882142e+16 | F110: <p>Parfum fresh woody yang memberikan rasa tenang dan bebas seperti menyatu dengan alam.</p> <p>NOTES<br>TOP: Ozonic, Citrus, Armoise<br>MID: Water Flowers, Hedione, Woody<br>BASE: Akigalawood, Cedarwood, Sandalwood</p> <p>Cocok buat kamu yang suka parfum fresh dan earthy!</p> <p>- Long-Lasting Scent, tahan lama dengan aroma yang menyegarkan<br>- Nature Inspired Aroma, menghadirkan suasana rileks dan menenangkan<br>- Perfect for Daily Reset, cocok dipakai untuk menemani aktivitas harian</p> <p>Cara Pakai<br>- Semprot pada titik nadi dengan jarak 15-20 cm<br>- Tunggu hingga kering</p>
A111: 122877 | B111: RAE NIRA - Extrait de Parfum | C111: 60d4e2c6443396b9504d4beb | D111: 349000 | E111: 4.8275862e+15 | F111: <p>Parfum yang menyimpan rasa hangat dan akrab, seperti memori lembut yang menenangkan lewat eucalyptus dan balsamic warmth.</p> <p>NOTES<br>TOP: Eucalyptus<br>MID: Immortelle<br>BASE: Tolu Balsam</p> <p>Cocok buat kamu yang suka parfum aromatic balsamic yang warm dan comforting!</p> <p>- Long-Lasting Scent, tahan lama untuk menemani aktivitasmu<br>- Perfect for Daily Wear, wangi yang pas dan nyaman untuk aktivitas sehari-hari</p> <p>Cara Pakai<br>- Semprot pada titik nadi dengan jarak 15-20 cm<br>- Tunggu hingga kering</p>
A112: 122235 | B112: Project 1945 Princess of Java Hair & Body Mist Unisex | HBM 150ml | C112: 64bf8ffd47133c15bf961d74 | D112: 145000 | E112: 4.8148148e+15 | F112: <p>Hair &amp; Body Mist Princess of Java, dari segarnya Pear Hijau, manisnya Tuberose, dan lembutnya Jasmine. Adalah sebuah wewangian mist yang ringan, multifungsi, dan menyegarkan untuk menjadi teman setia kamu!<br><br><br><br>Dilengkapi dengan tambahan formulasi Hydrogenated Castor Oil, Sunflower Seed Oil, dan Jojoba Seed Oil untuk membantu menjaga dan menutrisi rambut serta kulit kamu.</p><p>Fruity, Floral</p>
... A123: 107235 | B123: Madly, Deeply, Loved | C123: 6510fae507d9f80342bc6d05 | D123: 299000 | E123: 4.6458333e+15 | F123: <p>Parfum yang menghadirkan rasa hangat dan dalam seperti dicintai sepenuhnya.</p> <p>NOTES<br>TOP: Grapefruit, Pepper, Cinnamon, Rhubarb<br>MID: Saffron, Rose, Tea, Olibanum<br>BASE: Sandalwood, Patchouli Dust, French Vetiver, Vanilla</p> <p>Cocok buat kamu yang suka parfum spicy floral yang romantis!</p> <p>- Long-Lasting Scent, tahan lama dengan karakter yang elegan<br>- Romantic &amp; Warm Aroma, memberikan kesan hangat dan mendalam<br>- Perfect for Special Moments, cocok dipakai saat momen spesial</p> <p>Cara Pakai<br>- Semprot pada titik nadi dengan jarak 15-20 cm<br>- Tunggu hingga kering</p>
A124: 124742 | B124: Pink Beach 50ml Eau de Parfum | C124: 66fba216e8005543698af0d8 | D124: 199000 | E124: 5.0 | F124: <p>Buah juniper, buket bunga, dan aroma bedak menyeimbangkan wewangian, menciptakan sensasi tenang dan damai dari seprai linen. Bersantai di tempat tidur Anda, membaca buku favorit Anda dengan musik balada lembut yang diputar di latar belakang, dengan sinar matahari keemasan yang hangat menyaring melalui jendela besar, membelai Anda dalam pelukannya yang menenangkan.</p>
